<?xml version="1.0" encoding="utf-8"?><testsuites><testsuite name="pytest" errors="1" failures="0" skipped="0" tests="1" time="0.141" timestamp="2024-07-06T20:04:22.290307" hostname="Mohammeds-MacBook-Pro.local"><testcase classname="pytest" name="internal" time="0.000"><error message="internal error">Traceback (most recent call last):
  File "/Library/Frameworks/Python.framework/Versions/3.8/lib/python3.8/site-packages/_pytest/main.py", line 285, in wrap_session
    session.exitstatus = doit(config, session) or 0
  File "/Library/Frameworks/Python.framework/Versions/3.8/lib/python3.8/site-packages/_pytest/main.py", line 339, in _main
    config.hook.pytest_runtestloop(session=session)
  File "/Library/Frameworks/Python.framework/Versions/3.8/lib/python3.8/site-packages/pluggy/_hooks.py", line 513, in __call__
    return self._hookexec(self.name, self._hookimpls.copy(), kwargs, firstresult)
  File "/Library/Frameworks/Python.framework/Versions/3.8/lib/python3.8/site-packages/pluggy/_manager.py", line 120, in _hookexec
    return self._inner_hookexec(hook_name, methods, kwargs, firstresult)
  File "/Library/Frameworks/Python.framework/Versions/3.8/lib/python3.8/site-packages/pluggy/_callers.py", line 139, in _multicall
    raise exception.with_traceback(exception.__traceback__)
  File "/Library/Frameworks/Python.framework/Versions/3.8/lib/python3.8/site-packages/pluggy/_callers.py", line 122, in _multicall
    teardown.throw(exception)  # type: ignore[union-attr]
  File "/Library/Frameworks/Python.framework/Versions/3.8/lib/python3.8/site-packages/_pytest/logging.py", line 807, in pytest_runtestloop
    return (yield)  # Run all the tests.
  File "/Library/Frameworks/Python.framework/Versions/3.8/lib/python3.8/site-packages/pluggy/_callers.py", line 103, in _multicall
    res = hook_impl.function(*args)
  File "/Library/Frameworks/Python.framework/Versions/3.8/lib/python3.8/site-packages/_pytest/main.py", line 364, in pytest_runtestloop
    item.config.hook.pytest_runtest_protocol(item=item, nextitem=nextitem)
  File "/Library/Frameworks/Python.framework/Versions/3.8/lib/python3.8/site-packages/pluggy/_hooks.py", line 513, in __call__
    return self._hookexec(self.name, self._hookimpls.copy(), kwargs, firstresult)
  File "/Library/Frameworks/Python.framework/Versions/3.8/lib/python3.8/site-packages/pluggy/_manager.py", line 120, in _hookexec
    return self._inner_hookexec(hook_name, methods, kwargs, firstresult)
  File "/Library/Frameworks/Python.framework/Versions/3.8/lib/python3.8/site-packages/pluggy/_callers.py", line 139, in _multicall
    raise exception.with_traceback(exception.__traceback__)
  File "/Library/Frameworks/Python.framework/Versions/3.8/lib/python3.8/site-packages/pluggy/_callers.py", line 122, in _multicall
    teardown.throw(exception)  # type: ignore[union-attr]
  File "/Library/Frameworks/Python.framework/Versions/3.8/lib/python3.8/site-packages/_pytest/warnings.py", line 111, in pytest_runtest_protocol
    return (yield)
  File "/Library/Frameworks/Python.framework/Versions/3.8/lib/python3.8/site-packages/pluggy/_callers.py", line 122, in _multicall
    teardown.throw(exception)  # type: ignore[union-attr]
  File "/Library/Frameworks/Python.framework/Versions/3.8/lib/python3.8/site-packages/_pytest/assertion/__init__.py", line 176, in pytest_runtest_protocol
    return (yield)
  File "/Library/Frameworks/Python.framework/Versions/3.8/lib/python3.8/site-packages/pluggy/_callers.py", line 122, in _multicall
    teardown.throw(exception)  # type: ignore[union-attr]
  File "/Library/Frameworks/Python.framework/Versions/3.8/lib/python3.8/site-packages/_pytest/unittest.py", line 422, in pytest_runtest_protocol
    res = yield
  File "/Library/Frameworks/Python.framework/Versions/3.8/lib/python3.8/site-packages/pluggy/_callers.py", line 122, in _multicall
    teardown.throw(exception)  # type: ignore[union-attr]
  File "/Library/Frameworks/Python.framework/Versions/3.8/lib/python3.8/site-packages/_pytest/faulthandler.py", line 85, in pytest_runtest_protocol
    return (yield)
  File "/Library/Frameworks/Python.framework/Versions/3.8/lib/python3.8/site-packages/pluggy/_callers.py", line 103, in _multicall
    res = hook_impl.function(*args)
  File "/Library/Frameworks/Python.framework/Versions/3.8/lib/python3.8/site-packages/_pytest/runner.py", line 116, in pytest_runtest_protocol
    runtestprotocol(item, nextitem=nextitem)
  File "/Library/Frameworks/Python.framework/Versions/3.8/lib/python3.8/site-packages/_pytest/runner.py", line 129, in runtestprotocol
    rep = call_and_report(item, "setup", log)
  File "/Library/Frameworks/Python.framework/Versions/3.8/lib/python3.8/site-packages/_pytest/runner.py", line 243, in call_and_report
    report: TestReport = ihook.pytest_runtest_makereport(item=item, call=call)
  File "/Library/Frameworks/Python.framework/Versions/3.8/lib/python3.8/site-packages/pluggy/_hooks.py", line 513, in __call__
    return self._hookexec(self.name, self._hookimpls.copy(), kwargs, firstresult)
  File "/Library/Frameworks/Python.framework/Versions/3.8/lib/python3.8/site-packages/pluggy/_manager.py", line 120, in _hookexec
    return self._inner_hookexec(hook_name, methods, kwargs, firstresult)
  File "/Library/Frameworks/Python.framework/Versions/3.8/lib/python3.8/site-packages/pluggy/_callers.py", line 156, in _multicall
    teardown[0].send(outcome)
  File "/Users/ibrahim/SeleniumProjects/SeleniumPythonFramework/tests/conftest.py", line 54, in pytest_runtest_makereport
    _capture_screenshot(file_name)
  File "/Users/ibrahim/SeleniumProjects/SeleniumPythonFramework/tests/conftest.py", line 63, in _capture_screenshot
    driver.get_screenshot_as_file(name)
AttributeError: 'NoneType' object has no attribute 'get_screenshot_as_file'</error></testcase></testsuite></testsuites>